Workbook

Sheet Base
A1: Establecimientos con enseñanza media (1° a 4° medio) de la comuna de Coquimbo
A2: Corte: 23.10.2026. Se filtró la base 2.1 (Directorio Oficial MINEDUC 2025) y quedan los 43 establecimientos que imparten enseñanza media regular, científico-humanista (HC) o técnico-profesional (TP). La matrícula 2025 es la total del establecimiento, de todos sus niveles. Celdas amarillas: por completar.
A4: N° | B4: RBD | C4: Nombre | D4: Dependencia | E4: Niveles | F4: Zona | G4: Matrícula 2025 | H4: Director | I4: Fono institucional | J4: E-mail | K4: Dirección | L4: Aniversario | M4: Año de fundación | N4: Reconocimiento oficial (MINEDUC) | O4: Presidente/a centro de estudiantes | P4: Cargo (gobierno estudiantil) | Q4: Correo presidente/a CEAL | R4: Fuente CEAL | S4: Sitio web | T4: Sostenedor | U4: Latitud | V4: Longitud | W4: Fuente contacto | X4: Fuente aniversario | Y4: Observaciones
A5: 1 | B5: 616 | C5: Colegio Cardenal Jose Maria Caro | D5: Pública (SLEP Puerto Cordillera) | E5: Parvularia, Básica, Media HC | F5: Urbana | G5: 651 | H5: Domitila Pérez Díaz | I5: +56 44 369 1107 | J5: esc.cardenaljosemariacaro@slepuertocordillera.cl | K5: Cardenal Caro N°701- sector El Llano | L5: Sin información | M5: Sin información | N5: Resolución exenta 10049 de fecha 15/12/1981 | O5: Annais Victoria Badilla Valdivia | P5: Presidenta | Q5: annaisbadillavaldivia@gmail.com | R5: SLEP Puerto Cordillera, nómina presidentas/es centros de estudiantes 2026 | T5: Servicio Local De Educación Pública Puerto Cordillera | U5: -29.96734 | V5: -71.339104 | W5: SLEP Puerto Cordillera, tabla de establecimientos (act. 07.05.2026) | Y5: Director según tabla SLEP; MIME registra a Eduardo Andrés Alfaro Espinoza: confirmar
A6: 2 | B6: 629 | C6: Colegio Pablo Neruda | D6: Pública (SLEP Puerto Cordillera) | E6: Parvularia, Básica, Media HC, Media TP | F6: Rural | G6: 741 | H6: Manuel Salas López | I6: +56 51 223 9861 | J6: col.pabloneruda@slepuertocordillera.cl | K6: RUTA D409 Km 18 – Camino Interior N°9505 – Pan de Azúcar | L6: Julio (celebración) | M6: 1891 | N6: Resolución exenta 10046 de fecha 15/12/1981 | O6: Antonia Vera Cofré | P6: Presidenta | Q6: cofre.antonia30@gmail.com | R6: SLEP Puerto Cordillera, nómina presidentas/es centros de estudiantes 2026 | T6: Servicio Local De Educación Pública Puerto Cordillera | U6: -30.05068 | V6: -71.252403 | W6: SLEP Puerto Cordillera, tabla de establecimientos (act. 07.05.2026) | X6: Noticias SLEP Puerto Cordillera (128 años, julio 2019) | Y6: Director según tabla SLEP; MIME registra a Carla Francisca Álvarez Ibáñez: confirmar
A7: 3 | B7: 613 | C7: Colegio de Artes Claudio Arrau | D7: Pública (SLEP Puerto Cordillera) | E7: Parvularia, Básica, Media HC | F7: Urbana | G7: 755 | H7: Jorge Alberto Ríos Ruiz | I7: +56 51 232 8751 | J7: col.artesclaudioarrau@slepuertocordillera.cl | K7: Avda. Videla N°199 | L7: 3 de septiembre (PEI); el acto se ha celebrado en mayo | M7: 1834 | N7: Resolución exenta 10034 de fecha 15/12/1981 | O7: Amparo Daira Yañez Nuñez | P7: Presidenta | Q7: ayanezn2872@gmail.com | R7: SLEP Puerto Cordillera, nómina presidentas/es centros de estudiantes 2026 | S7: www.arraucoquimbo.cl | T7: Servicio Local De Educación Pública Puerto Cordillera | U7: -29.961269 | V7: -71.338287 | W7: SLEP Puerto Cordillera, tabla de establecimientos (act. 07.05.2026) | X7: PEI del establecimiento (MINEDUC); Noticias SLEP Puerto Cordillera (177° aniversario, mayo 2019) | Y7: Según MIME; el director que figura en la tabla del SLEP (Carlos Videla) pasó al IAC Estado de Israel en mayo de 2026: confirmar si es titular o subrogante
A8: 4 | B8: 13558 | C8: Instituto de Adm. y Comercio Estado de Israel | D8: Pública (SLEP Puerto Cordillera) | E8: Básica, Media TP | F8: Urbana | G8: 592 | H8: Carlos Videla Bonilla | I8: +56 51 231 9395 | J8: iac.estadodeisrael@slepuertocordillera.cl | K8: Manuel Jesús Rivera N°320 – sector San Juan | L8: Mayo (celebración) | M8: 2005 | N8: Resolución exenta 1452 de fecha 06/05/2005 | O8: Catalina Pavez Fuenzalida | P8: Presidenta | Q8: catalinapavezfuenzalida@gmail.com | R8: SLEP Puerto Cordillera, nómina presidentas/es centros de estudiantes 2026 | T8: Servicio Local De Educación Pública Puerto Cordillera | U8: -29.970631 | V8: -71.325447 | W8: SLEP Puerto Cordillera, tabla de establecimientos (act. 07.05.2026) | X8: Noticias SLEP Puerto Cordillera (14 años, mayo 2019) | Y8: Asumió por concurso de Alta Dirección Pública (SLEP, noticia 04.05.2026); la tabla del SLEP aún muestra al director anterior
A9: 5 | B9: 13561 | C9: Lic.De Cienc.Y Hum.San Josemaria Escriva | D9: Pública (SLEP Puerto Cordillera) | E9: Básica, Media HC | F9: Urbana | G9: 519 | H9: Jaime Miranda Manríquez | I9: +56 51 226 8461 | J9: lic.josemariaescriva@slepuertocordillera.cl | K9: Los Clarines N°1871 | L9: 1 de septiembre | M9: 2005 | N9: Resolución exenta 1451 de fecha 06/05/2005 | O9: Ángela Muñoz Véliz | P9: Presidenta | Q9: angemunozve08@gmail.com | R9: SLEP Puerto Cordillera, nómina presidentas/es centros de estudiantes 2026 | T9: Servicio Local De Educación Pública Puerto Cordillera | U9: -29.990379 | V9: -71.331596 | W9: SLEP Puerto Cordillera, tabla de establecimientos (act. 07.05.2026) | X9: PEI del establecimiento (MINEDUC); Noticias SLEP Puerto Cordillera
A10: 6 | B10: 609 | C10: Liceo Bicentenario de Excelencia Instituto Superior de Comercio de Coquimbo | D10: Pública (SLEP Puerto Cordillera) | E10: Media TP | F10: Urbana | G10: 838 | H10: Fernando Carvajal Araya | I10: +56 51 232 1092 / +56 51 231 3968 | J10: isc.coquimbo@slepuertocordillera.cl | K10: Doctor Marín N°367 | L10: 10 de mayo | M10: 1905 | N10: Resolución exenta 339 de fecha 01/03/2018 | O10: Javiera Peña Velásquez | P10: Presidenta | Q10: javierapenavelasquez@gmail.com | R10: SLEP Puerto Cordillera, nómina presidentas/es centros de estudiantes 2026 | S10: www.isccoquimbo.cl | T10: Servicio Local De Educación Pública Puerto Cordillera | U10: -29.96055 | V10: -71.340134 | W10: SLEP Puerto Cordillera, tabla de establecimientos (act. 07.05.2026) | X10: PEI del establecimiento (MINEDUC); Noticias SLEP Puerto Cordillera (120 años, mayo 2025)
A11: 7 | B11: 13461 | C11: Liceo Carmen Aurora Rodriguez Henriquez | D11: Pública (SLEP Puerto Cordillera) | E11: Media HC, Media TP, Adultos | F11: Urbana | G11: 353 | H11: Perla Araya Yañez | I11: +56 51 239 1570 | J11: lic.carmenrodriguez@slepuertocordillera.cl | K11: Dolores Endeiza N°185 – Tongoy | L11: 2 de agosto | M11: 2000 | N11: Resolución exenta 1765 de fecha 02/08/2000 | O11: Sebastián Ignacio Saavedra Henríquez | P11: Presidente | Q11: alex55521332@gmail.com | R11: SLEP Puerto Cordillera, nómina presidentas/es centros de estudiantes 2026 | T11: Servicio Local De Educación Pública Puerto Cordillera | U11: -30.26264 | V11: -71.493401 | W11: SLEP Puerto Cordillera, tabla de establecimientos (act. 07.05.2026) | X11: PEI del establecimiento (MINEDUC); Noticias SLEP Puerto Cordillera
A12: 8 | B12: 611 | C12: Liceo Diego Portales | D12: Pública (SLEP Puerto Cordillera) | E12: Media HC, Media TP, Adultos | F12: Urbana | G12: 474 | H12: Neusy Elizabeth Chelmes Julio | I12: +56 51 232 1015 | J12: lic.diegoportales@slepuertocordillera.cl | K12: Avda. Francisco Varela Oriente N°950 | L12: 5 de abril | M12: 1956 | N12: Resolución exenta 10070 de fecha 15/12/1981 | O12: Sofía Bruna Muñoz | P12: Presidenta de gobierno estudiantil | Q12: sofiab.bruna.munoz@gmail.com | R12: SLEP Puerto Cordillera, nómina presidentas/es centros de estudiantes 2026 | T12: Servicio Local De Educación Pública Puerto Cordillera | U12: -29.95303 | V12: -71.337021 | W12: SLEP Puerto Cordillera, tabla de establecimientos (act. 07.05.2026) | X12: PEI del establecimiento (MINEDUC); Noticias SLEP Puerto Cordillera | Y12: Asumió por concurso de Alta Dirección Pública (SLEP, noticia 04.05.2026); la tabla del SLEP aún muestra al director anterior
A13: 9 | B13: 11139 | C13: Liceo Fernando Binvignat Marin | D13: Pública (SLEP Puerto Cordillera) | E13: Media TP | F13: Urbana | G13: 675 | H13: Vladimir Fuentes Jorquera | I13: +56 44 369 2430 | J13: lic.fernandobinvignat@slepuertocordillera.cl | K13: Arauco N°1050 – Ts. Blancas | L13: 18 de marzo | M13: 1986 (inicio como anexo en 1983) | N13: Resolución exenta 216 de fecha 18/03/1986 | O13: Luciana Fernández Guerrero | P13: Presidenta | Q13: lic.fernandobinvignat@slepuertocordillera.cl (correo del establecimiento) | R13: SLEP Puerto Cordillera, nómina presidentas/es centros de estudiantes 2026 | S13: www.liceobinvignat.cl | T13: Servicio Local De Educación Pública Puerto Cordillera | U13: -29.963869 | V13: -71.254288 | W13: SLEP Puerto Cordillera, tabla de establecimientos (act. 07.05.2026) | X13: PEI del establecimiento (MINEDUC)
A14: 10 | B14: 610 | C14: Liceo Industrial Jose Tomas de Urmeneta | D14: Pública (SLEP Puerto Cordillera) | E14: Media TP | F14: Urbana | G14: 583 | H14: Jorge Carvajal Araya | I14: +56 44 369 1128 | J14: lic.industrialjosetomas@slepuertocordillera.cl | K14: Ossandón N°1000 | L14: 25 de mayo | M14: 1966 | N14: Resolución exenta 1075 de fecha 21/11/1983 | O14: Maverick Grosling | P14: Presidente | Q14: mav.gross1617@gmail.com | R14: SLEP Puerto Cordillera, nómina presidentas/es centros de estudiantes 2026 | T14: Servicio Local De Educación Pública Puerto Cordillera | U14: -29.96525 | V14: -71.347221 | W14: SLEP Puerto Cordillera, tabla de establecimientos (act. 07.05.2026) | X14: PEI del establecimiento (MINEDUC)
A15: 11 | B15: 20505 | C15: Aula Hospitalaria de Coquimbo | D15: Particular subvencionado | E15: Parvularia, Básica, Media HC | F15: Urbana | G15: 118 | H15: Martín Hernando Perez-cueto Deza | I15: +56 51 267 4683 | J15: coquimbo@ahss.cl | K15: Cirujano Videla Sn | L15: Sin información | M15: 2010 | N15: Resolución exenta 1632 de fecha 30/06/2016 | O15: Por completar | S15: www.ahss.cl | T15: Aulas Hospitalarias San Sebastian E.i.e. | U15: -29.968593 | V15: -71.337826 | W15: MINEDUC, Ficha del Establecimiento (MIME), consulta 05.10.2026 | X15: PEI del establecimiento (MINEDUC)
A16: 12 | B16: 40064 | C16: Colegio Alta Cordillera | D16: Particular subvencionado | E16: Parvularia, Básica, Media HC, Adultos | F16: Urbana | G16: 614 | H16: Cecilia Marcela Tamayo Plaza | I16: +56 51 231 7507 | J16: direccionaltacordillera@gmail.com | K16: Cardenal Carlos Oviedo 3380 | L16: 30 de junio (reconocimiento oficial) | M16: 2008 | N16: Resolución exenta 1888 de fecha 29/06/2018 | O16: Por completar | S16: www.altacordilleracoquimbo.cl | T16: Corporación Educacional Alta Cordillera | U16: -29.970329 | V16: -71.310333 | W16: MINEDUC, Ficha del Establecimiento (MIME), consulta 05.10.2026 | X16: PEI del establecimiento (MINEDUC)
A17: 13 | B17: 13491 | C17: Colegio Altazor | D17: Particular subvencionado | E17: Parvularia, Básica, Media HC | F17: Urbana | G17: 960 | H17: Ingrid Marlene Itha Hornig Saldías | I17: +56 51 223 2193 | J17: colegioaltazorcqbo@gmail.com | K17: Regimiento Arica 700 | L17: Sin información | M17: 2002 | N17: Resolución exenta 1875 de fecha 29/06/2018 | O17: Por completar | S17: www.colegioaltazor.cl | T17: Corporacion Educacional Altazor De Coquimbo | U17: -29.951099 | V17: -71.266968 | W17: MINEDUC, Ficha del Establecimiento (MIME), consulta 05.10.2026 | X17: PEI del establecimiento (MINEDUC)
A18: 14 | B18: 646 | C18: Colegio Bernardo O´Higgins | D18: Particular subvencionado | E18: Parvularia, Básica, Media HC, Media TP | F18: Urbana | G18: 1765 | H18: Wilson Ismael Puelles Jopia | I18: +56 51 231 3192 | J18: bernardoohigginscqbo@gmail.com | K18: Avenida Matta 86 | L18: Sin información | M18: Sin información | N18: Resolución exenta 1790 de fecha 29/06/2018 | O18: Por completar | S18: www.cbo.cl | T18: Corporacion Educacional Colegio Bernardo O` Higgins- Coquimbo | U18: -29.96076 | V18: -71.337341 | W18: MINEDUC, Ficha del Establecimiento (MIME), consulta 05.10.2026
A19: 15 | B19: 13314 | C19: Colegio Cristobal Colon | D19: Particular subvencionado | E19: Parvularia, Básica, Media HC | F19: Urbana | G19: 924 | H19: Angélica Del Rosario Bravo Salas | I19: +56 51 226 5624 | J19: dinko.koscina@fundacioncolon.cl | K19: Los Clarines 2201 | L19: Sin información | M19: 1994 | N19: Resolución exenta 1874 de fecha 29/06/2018 | O19: Por completar | S19: colegiocolon.cl | T19: Fundación Educacional Colón | U19: -29.99188 | V19: -71.330429 | W19: MINEDUC, Ficha del Establecimiento (MIME), consulta 05.10.2026 | X19: PEI del establecimiento (MINEDUC)
A20: 16 | B20: 13621 | C20: Colegio Discovery | D20: Particular subvencionado | E20: Parvularia, Básica, Media HC | F20: Urbana | G20: 504 | H20: Debbie Karin Álvarez Gutiérrez | I20: +56 51 252 0027 | J20: directora@discoveryschool.cl | K20: Pedro Lagos , Sector El Llano 721 | L20: Sin información | M20: 2007 | N20: Resolución exenta 1853 de fecha 29/06/2018 | O20: Por completar | S20: discoveryschool.cl | T20: Corporación Educacional Aventura | U20: -29.967319 | V20: -71.344543 | W20: MINEDUC, Ficha del Establecimiento (MIME), consulta 05.10.2026 | X20: PEI del establecimiento (MINEDUC)
A21: 17 | B21: 13445 | C21: Colegio Espanol | D21: Particular subvencionado | E21: Media HC | F21: Urbana | G21: 170 | H21: Giannina Andrea De Los Angeles Lotito Manterola | I21: +56 51 254 9114 | J21: cespa_q@hotmail.com | K21: Avenida Alessandri 303 | L21: 12 de octubre | M21: 1998 | N21: Resolución exenta 1929 de fecha 29/06/2018 | O21: Por completar | T21: Corporación Educacional Colegio Español | U21: -29.966181 | V21: -71.341133 | W21: MINEDUC, Ficha del Establecimiento (MIME), consulta 05.10.2026 | X21: PEI del establecimiento (MINEDUC)
A22: 18 | B22: 13313 | C22: Colegio Francis School | D22: Particular subvencionado | E22: Parvularia, Básica, Media HC | F22: Urbana | G22: 2130 | H22: Francis Gema Oyarzún Caru | I22: +56 51 226 6562 | J22: frangecar@gmail.com | K22: Los Tulipanes 254 | L22: Sin información | M22: 1990 (jardín) / 1991 (colegio) | N22: Resolución exenta 0765 de fecha 27/06/1990 | O22: Por completar | S22: www.francisschool.cl | T22: Fundación Educacional Francis School | U22: -29.977051 | V22: -71.34169 | W22: MINEDUC, Ficha del Establecimiento (MIME), consulta 05.10.2026 | X22: PEI del establecimiento (MINEDUC)
A23: 19 | B23: 647 | C23: Colegio Manuel Montt | D23: Particular subvencionado | E23: Básica, Media HC | F23: Urbana | G23: 485 | H23: Danisa Tatiana Bonilla Cabezas | I23: +56 9 9193 3967 | J23: colegiomanuelmontt@gmail.com | K23: Los Espinos Sur 2715 El Sauce Miramar | L23: Sin información | M23: Sin información | N23: Resolución exenta 1882 de fecha 29/06/2018 | O23: Por completar | S23: colegiomanuelmontt.cl | T23: Corporación Educacional Manuel Montt | U23: -29.999411 | V23: -71.335777 | W23: MINEDUC, Ficha del Establecimiento (MIME), consulta 05.10.2026 | Y23: Celular antiguo de 8 dígitos, se antepuso 9: verificar
A24: 20 | B24: 13489 | C24: Colegio Maria Educa | D24: Particular subvencionado | E24: Parvularia, Básica, Media HC | F24: Urbana | G24: 963 | H24: Susana Del Carmen Salgado Cardemil | I24: +56 51 223 0423 | J24: graciela.guerrero@mariaeduca.cl | K24: Fray Jorge, Bosque San Carlos 850 | L24: Sin información | M24: Sin información | N24: Resolución exenta 843 de fecha 09/05/2002 | O24: Por completar | S24: www.mariaeduca.cl | T24: Fundacion Maria Educa | U24: -29.97242 | V24: -71.256821 | W24: MINEDUC, Ficha del Establecimiento (MIME), consulta 05.10.2026
A25: 21 | B25: 650 | C25: Colegio Metodista de Coquimbo | D25: Particular subvencionado | E25: Parvularia, Básica, Media HC | F25: Urbana | G25: 423 | H25: Luis Eduardo Contreras Aguilar | I25: +56 51 240 0150 | J25: contacto@escuelametodista.cl | K25: San Martin 1598 | L25: 13 de agosto | M25: 1953 | N25: Resolución exenta 993 de fecha 15/05/2017 | O25: Por completar | S25: www.escuelametodista.cl | T25: Corporacion Metodista | U25: -29.957479 | V25: -71.343391 | W25: MINEDUC, Ficha del Establecimiento (MIME), consulta 05.10.2026 | X25: PEI del establecimiento (MINEDUC)
A26: 22 | B26: 13341 | C26: Colegio Part. Komvux - Coquimbo | D26: Particular subvencionado | E26: Parvularia, Básica, Media HC, Media TP | F26: Urbana | G26: 286 | H26: Carolina Luisa Muñoz Carvajal | I26: +56 2 2857 3495 | J26: colegiokomvuxcoquimbo@gmail.com | K26: Av. Pdte. Arturo Alessandri 1859 | L26: Sin información | M26: 1993 | N26: Resolución exenta 1296 de fecha 09/05/2018 | O26: Por completar | S26: www.colegiokomvux.cl | T26: Corporacion Educacional Colegio Komvux | U26: -29.983101 | V26: -71.334297 | W26: MINEDUC, Ficha del Establecimiento (MIME), consulta 05.10.2026 | X26: PEI del establecimiento (MINEDUC) | Y26: Prefijo de Santiago: verificar
A27: 23 | B27: 11145 | C27: Colegio Particular Calasanz | D27: Particular subvencionado | E27: Parvularia, Básica, Media HC | F27: Urbana | G27: 604 | H27: Enrique Roberto Arenas Otárola | I27: +56 51 224 1497 | J27: colegio@calasanztb.cl | K27: Valdivia 951 | L27: Sin información | M27: Sin información | N27: Resolución exenta 317 de fecha 07/04/1987 | O27: Por completar | S27: calasanztb.cl | T27: Pio Instituto Hijas De Maria Religiosas De Las Escuelas Pias | U27: -29.966249 | V27: -71.256844 | W27: MINEDUC, Ficha del Establecimiento (MIME), consulta 05.10.2026
A28: 24 | B28: 649 | C28: Colegio Particular Gabriela Mistral | D28: Particular subvencionado | E28: Parvularia, Básica, Media HC | F28: Urbana | G28: 1496 | H28: Luisa Mariela De Lourdes Cuello Yuschkewitz | I28: +56 51 231 1577 | J28: colgami@gmail.com | K28: Abtao 22 | L28: Sin información | M28: Sin información | N28: Resolución exenta 01240 de fecha 15/09/1982 | O28: Por completar | S28: www.colegiogabrielamistralcoquimbo.cl | T28: Corporación Colegio Gabriela Mistral De Coquimbo | U28: -29.963671 | V28: -71.339043 | W28: MINEDUC, Ficha del Establecimiento (MIME), consulta 05.10.2026
A29: 25 | B29: 13373 | C29: Colegio Particular Leonardo Da Vinci | D29: Particular subvencionado | E29: Parvularia, Básica, Media HC | F29: Urbana | G29: 918 | H29: Alejandra Angélica Román Calquín | I29: +56 51 224 8772 | J29: secretaria@davincicoquimbo.cl | K29: Juan Barrera Cortes - El Agrado De Penuelas 2050 | L29: Marzo (inicio de clases) | M29: 1995 | N29: Resolución exenta 1887 de fecha 29/06/2018 | O29: Por completar | S29: www.davincicoquimbo.cl | T29: Corporación Educacional Peñuelas | U29: -29.95256 | V29: -71.270157 | W29: MINEDUC, Ficha del Establecimiento (MIME), consulta 05.10.2026 | X29: PEI del establecimiento (MINEDUC)
A30: 26 | B30: 11133 | C30: Colegio Particular San Gabriel | D30: Particular subvencionado | E30: Básica, Media HC | F30: Urbana | G30: 300 | H30: Aída Ester Segovia Álvarez | I30: +56 9 9770 1573 | J30: colegiosangabrielcoquimbo@gmail.com | K30: Eleuterio Ramirez 440 | L30: Sin información | M30: Sin información | N30: Resolución exenta 22254 de fecha 23/11/2017 | O30: Por completar | T30: San Gabriel Arcangel E.i.e. | U30: -29.962021 | V30: -71.339333 | W30: MINEDUC, Ficha del Establecimiento (MIME), consulta 05.10.2026 | Y30: Celular antiguo de 8 dígitos, se antepuso 9: verificar
A31: 27 | B31: 13604 | C31: Colegio Rakiduam | D31: Particular subvencionado | E31: Parvularia, Básica, Media HC | F31: Urbana | G31: 590 | H31: Carolina Del Carmen Pizarro Lagos | I31: +56 51 254 6103 | J31: direccion@colegiorakiduam.cl | K31: Avenida La Cantera 610 | L31: Sin información | M31: 2006 | N31: Resolución exenta 1788 de fecha 29/06/2018 | O31: Por completar | S31: www.colegiorakiduam.cl | T31: Fundación Educacional Rakiduam | U31: -29.9666 | V31: -71.31031 | W31: MINEDUC, Ficha del Establecimiento (MIME), consulta 05.10.2026 | X31: PEI del establecimiento (MINEDUC) | Y31: Número antiguo de 6 dígitos, se antepuso 2: verificar
A32: 28 | B32: 13504 | C32: Colegio San Lorenzo | D32: Particular subvencionado | E32: Parvularia, Básica, Media HC | F32: Urbana | G32: 1255 | H32: Soledad Del Rosario Salazar Aracena | I32: +56 51 227 7056 | J32: soledad.salazar.ara20@colsanlorenzo.cl | K32: Narciso Herrera 2575 | L32: Sin información | M32: Sin información | N32: Resolución exenta 578 de fecha 16/03/2018 | O32: Por completar | S32: www.colegiosanlorenzolacantera.cl | T32: Corporación Colegio San Lorenzo De Coquimbo | U32: -29.97743 | V32: -71.293388 | W32: MINEDUC, Ficha del Establecimiento (MIME), consulta 05.10.2026
A33: 29 | B33: 13626 | C33: Colegio San Luis | D33: Particular subvencionado | E33: Parvularia, Básica, Media HC | F33: Urbana | G33: 358 | H33: Dafne Yarella Zúñiga Carvajal | I33: +56 51 254 6240 | J33: luiggi@wilug.cl | K33: Avda Ossandon 350 | L33: Sin información | M33: Sin información | N33: Resolución exenta 238 de fecha 13/02/2018 | O33: Por completar | S33: www.instagram.com/colegio_sanluis_coquimbo/ | T33: Corporación Educacional San Luis De Coquimbo | U33: -29.96158 | V33: -71.342957 | W33: MINEDUC, Ficha del Establecimiento (MIME), consulta 05.10.2026
A34: 30 | B34: 13442 | C34: Colegio Santa Familia | D34: Particular subvencionado | E34: Parvularia, Básica, Media HC | F34: Urbana | G34: 1233 | H34: Pamela Carolina Arancibia Araya | I34: +56 51 226 6516 | J34: corporacionsanguillermo@colegiosantafamilia.cl | K34: Eduardo Mallea 601 | L34: Sin información | M34: 1999 | N34: Resolución exenta 756 de fecha 01/03/1999 | O34: Por completar | S34: www.colegiosantafamilia.cl | T34: Corporación Educacional San Guillermo | U34: -29.99054 | V34: -71.334129 | W34: MINEDUC, Ficha del Establecimiento (MIME), consulta 05.10.2026 | X34: PEI del establecimiento (MINEDUC)
A35: 31 | B35: 13553 | C35: Colegio Santa Helena College | D35: Particular subvencionado | E35: Media HC | F35: Urbana | G35: 115 | H35: Elena Adelaida Varela Sierra | I35: +56 9 8449 8473 | J35: santahelenacollege@gmail.com | K35: Avda Videla 235 | L35: Sin información | M35: Sin información | N35: Resolución exenta 1856 de fecha 29/06/2018 | O35: Por completar | S35: w.w.w.shcc.cl | T35: Corporacion Educacional Santa Helena College | U35: -29.96242 | V35: -71.337532 | W35: MINEDUC, Ficha del Establecimiento (MIME), consulta 05.10.2026
A36: 32 | B36: 13324 | C36: Colegio Santa Maria de Belen N_ 162 | D36: Particular subvencionado | E36: Parvularia, Básica, Media HC | F36: Urbana | G36: 809 | H36: Patricia Elena Castillo Oros | I36: +56 51 226 8040 | J36: secretariasmbelen@gmail.com | K36: Las Begonias Sindempart 361 - 371 | L36: Sin información | M36: Sin información | N36: Resolución exenta 1067 de fecha 16/06/1993 | O36: Por completar | S36: www.smbelenfranciscanas.cl | T36: Hermanas Franciscanas Misioneras De Jesus | U36: -29.98431 | V36: -71.34539 | W36: MINEDUC, Ficha del Establecimiento (MIME), consulta 05.10.2026 | Y36: Número antiguo de 6 dígitos, se antepuso 2: verificar
A37: 33 | B37: 648 | C37: Colegio Santa Marta | D37: Particular subvencionado | E37: Parvularia, Básica, Media HC | F37: Urbana | G37: 1125 | H37: María Isabel Castro Ríos | I37: +56 51 267 2760 | J37: fecosamarta@gmail.com | K37: Manuel Rodriguez 2110 | L37: Sin información | M37: Sin información | N37: Resolución exenta 5012 de fecha 19/11/1981 | O37: Por completar | S37: www.colegiosantamartacoquimbo.cl | T37: Fundacion Educacional Colegio Santa Marta Coq | U37: -29.96142 | V37: -71.34729 | W37: MINEDUC, Ficha del Establecimiento (MIME), consulta 05.10.2026
A38: 34 | B38: 40208 | C38: Colegio Tecnico Profesional Altue | D38: Particular subvencionado | E38: Básica, Media HC, Media TP | F38: Urbana | G38: 350 | H38: Sergio Sebastián Idilio Moraga Cruz | I38: +56 9 4000 5627 | J38: wgonzalezsulantay@gmail.com | K38: Cabo Exequiel Aroca 1340 | L38: 11 de marzo | M38: 2009 | N38: Resolución exenta 1785 de fecha 12/09/2016 | O38: Por completar | S38: www.colegioaltue.cl | T38: Corporaciòn Educacional Cristo De La Misericordia | U38: -29.953421 | V38: -71.248123 | W38: MINEDUC, Ficha del Establecimiento (MIME), consulta 05.10.2026 | X38: PEI del establecimiento (MINEDUC) | Y38: Celular antiguo de 8 dígitos, se antepuso 9: verificar
A39: 35 | B39: 11144 | C39: Escuela Diego de Almeyda | D39: Particular subvencionado | E39: Parvularia, Básica, Media HC, Media TP | F39: Urbana | G39: 1167 | H39: Pamela Ximena Antinao Plaza | I39: +56 51 224 0042 | J39: direccion@diegodealmeyda.cl | K39: Santiago 1244 | L39: 20 de marzo | M39: 1987 | N39: Resolución exenta 1534 de fecha 12/07/2017 | O39: Por completar | S39: www.diegodealmeyda.cl | T39: Corporación Educacional Diego De Almeyda | U39: -29.95982 | V39: -71.250908 | W39: MINEDUC, Ficha del Establecimiento (MIME), consulta 05.10.2026 | X39: PEI del establecimiento (MINEDUC)
A40: 36 | B40: 13633 | C40: Escuela San Marino College | D40: Particular subvencionado | E40: Parvularia, Básica, Media HC | F40: Urbana | G40: 492 | H40: Olivia Isabel Ponce López | I40: +56 51 260 5587 | J40: colegio@sanmarinocollege.cl | K40: Los Huertos 1731 | L40: 3 de marzo | M40: 2007 | N40: Resolución exenta 1777 de fecha 29/06/2018 | O40: Por completar | S40: www.sanmarinocollege.cl | T40: Corporacion Educacional San Marino | U40: -29.970921 | V40: -71.299721 | W40: MINEDUC, Ficha del Establecimiento (MIME), consulta 05.10.2026 | X40: PEI del establecimiento (MINEDUC)
A41: 37 | B41: 13361 | C41: Kid´S World School | D41: Particular subvencionado | E41: Parvularia, Básica, Media HC | F41: Urbana | G41: 997 | H41: Ricardo Alfonso Guerra Varela | I41: +56 51 260 5628 | J41: roxana.castillo@kidsworldschool.cl | K41: Ignacio Carrera Pinto El Llano 955 | L41: Sin información | M41: 1991 (como jardín) | N41: Resolución exenta 1797 de fecha 29/06/2018 | O41: Por completar | S41: www.kidsworldschool.cl | T41: Corporacion Educacional Kid´s World | U41: -29.964211 | V41: -71.342949 | W41: MINEDUC, Ficha del Establecimiento (MIME), consulta 05.10.2026 | X41: PEI del establecimiento (MINEDUC)
...

Sheet Resumen
A1: Resumen de la base
A3: Dependencia | B3: Establecimientos | C3: Matrícula total 2025 | D3: Con director informado | E3: Con aniversario (fecha o mes) | F3: Presidente/a CEAL informado | G3: CEAL por completar
A4: Pública (SLEP Puerto Cordillera) | B4: =COUNTIF(Base!$D$5:$D$47,A4) -> 10 | C4: =SUMIF(Base!$D$5:$D$47,A4,Base!$G$5:$G$47) -> 6181 | D4: =COUNTIFS(Base!$D$5:$D$47,A4,Base!$H$5:$H$47,"<>Sin información") -> 10 | E4: =COUNTIFS(Base!$D$5:$D$47,A4,Base!$L$5:$L$47,"<>Sin información") -> 9 | F4: =COUNTIFS(Base!$D$5:$D$47,A4,Base!$O$5:$O$47,"<>Por completar",Base!$O$5:$O$47,"<>No aplica") -> 10 | G4: =COUNTIFS(Base!$D$5:$D$47,A4,Base!$O$5:$O$47,"Por completar") -> 0
A5: Particular subvencionado | B5: =COUNTIF(Base!$D$5:$D$47,A5) -> 28 | C5: =SUMIF(Base!$D$5:$D$47,A5,Base!$G$5:$G$47) -> 22239 | D5: =COUNTIFS(Base!$D$5:$D$47,A5,Base!$H$5:$H$47,"<>Sin información") -> 28 | E5: =COUNTIFS(Base!$D$5:$D$47,A5,Base!$L$5:$L$47,"<>Sin información") -> 8 | F5: =COUNTIFS(Base!$D$5:$D$47,A5,Base!$O$5:$O$47,"<>Por completar",Base!$O$5:$O$47,"<>No aplica") -> 0 | G5: =COUNTIFS(Base!$D$5:$D$47,A5,Base!$O$5:$O$47,"Por completar") -> 28
A6: Particular pagado | B6: =COUNTIF(Base!$D$5:$D$47,A6) -> 5 | C6: =SUMIF(Base!$D$5:$D$47,A6,Base!$G$5:$G$47) -> 2228 | D6: =COUNTIFS(Base!$D$5:$D$47,A6,Base!$H$5:$H$47,"<>Sin información") -> 5 | E6: =COUNTIFS(Base!$D$5:$D$47,A6,Base!$L$5:$L$47,"<>Sin información") -> 1 | F6: =COUNTIFS(Base!$D$5:$D$47,A6,Base!$O$5:$O$47,"<>Por completar",Base!$O$5:$O$47,"<>No aplica") -> 0 | G6: =COUNTIFS(Base!$D$5:$D$47,A6,Base!$O$5:$O$47,"Por completar") -> 5
A7: Total | B7: =SUM(B4:B6) -> 43 | C7: =SUM(C4:C6) -> 30648 | D7: =SUM(D4:D6) -> 43 | E7: =SUM(E4:E6) -> 18 | F7: =SUM(F4:F6) -> 10 | G7: =SUM(G4:G6) -> 33
A9: Modalidad de enseñanza media | B9: Establecimientos
A10: Solo científico-humanista (HC) | B10: =COUNTIFS(Base!$E$5:$E$47,"*Media HC*",Base!$E$5:$E$47,"<>*Media TP*") -> 32
A11: Solo técnico-profesional (TP) | B11: =COUNTIFS(Base!$E$5:$E$47,"*Media TP*",Base!$E$5:$E$47,"<>*Media HC*") -> 4
A12: HC y TP (polivalente) | B12: =COUNTIFS(Base!$E$5:$E$47,"*Media HC*",Base!$E$5:$E$47,"*Media TP*") -> 7
A13: Total | B13: =SUM(B10:B12) -> 43
A15: La matrícula es la total de cada establecimiento en 2025 e incluye párvulos y básica cuando el colegio los tiene; no corresponde solo a enseñanza media.

Sheet Fuentes y notas
A1: Fuentes
A2: Universo | B2: MINEDUC, Directorio Oficial de Establecimientos 2025 (datosabiertos.mineduc.cl), comuna 4102, estado "funcionando". Filtro del 23.10.2026: solo los 43 establecimientos cuyo registro incluye enseñanza media regular HC o TP (1° a 4° medio), con matrícula 2025 informada.
A3: Contacto, establecimientos públicos | B3: SLEP Puerto Cordillera, página "Establecimientos Educacionales" (slepuertocordillera.gob.cl, última edición 07.05.2026). Correos decodificados de la página.
A4: Contacto, establecimientos particulares | B4: MINEDUC, Ficha del Establecimiento (mi.mineduc.cl), consultada el 05.10.2026. La información la carga cada director y puede estar desactualizada.
A5: Cambios de director | B5: SLEP Puerto Cordillera, noticia 04.05.2026: seis directores asumen por Alta Dirección Pública (cuatro en Coquimbo: IAC Estado de Israel, Liceo Diego Portales, Escuela República de Italia y Colegio Santa Cecilia). Se corrigieron en la base.
A6: Aniversarios | B6: Reseñas históricas de los Proyectos Educativos Institucionales (PEI) publicados en MINEDUC y noticias de aniversario del SLEP Puerto Cordillera. Donde no hay fecha de aniversario se indica "Sin información"; la columna de reconocimiento oficial es un dato distinto y no reemplaza al aniversario.
A7: Notas
A8: Teléfonos | B8: Se normalizaron a formato +56. Los números antiguos de 6 dígitos y los celulares de 8 dígitos se convirtieron según las reglas de numeración de 2013 y quedan marcados para verificar en Observaciones.
A9: Directores con dato distinto | B9: En 3 liceos y colegios públicos de esta selección la tabla del SLEP y MIME muestran directores distintos (Cardenal Caro, Pablo Neruda y Claudio Arrau). Se dejó el dato más reciente que se pudo respaldar y se marcó para confirmar en Observaciones.
A10: Presidentes de CEAL | B10: Establecimientos públicos: se integró la nómina 2026 de presidentas y presidentes de centros de estudiantes y gobiernos estudiantiles del SLEP Puerto Cordillera, cruzada por RBD. Particulares: no hay registro público y quedan 33 en amarillo ("Por completar"). Cuando el correo de la nómina es el institucional del establecimiento, se indica entre paréntesis.
A11: Resguardo de datos | B11: La nómina contiene nombres y correos personales de estudiantes, en su mayoría menores de edad. Usar solo para vinculación institucional, no difundir y no publicar la planilla (Ley 19.628 y Ley 21.719 sobre protección de datos personales). Para contactos formales, preferir el correo institucional del establecimiento con copia a la dirección.
A12: Fuera del universo | B12: Quedan fuera los establecimientos que solo imparten parvularia, básica o educación especial, los jardines VTF, JUNJI e Integra, y las instituciones de educación superior (están en la base 2.1). También los colegios que atienden solo a personas adultas, porque su enseñanza media es por niveles y no de 1° a 4° medio: Colegio Adultos San Luis, Adultos Las Violetas, CEIA Santa, Colegio Olimpo, Colegio de Jóvenes y Adultos Ossandón, Escuela para Adultos Amigos del Padre Hurtado, Instituto de Educación para el Adulto, Colegio de Adultos Su Santidad Juan Pablo II y Colegio José Martí Pérez (este último imparte parvularia, básica y adultos).
A13: Casos a mirar | B13: Tres establecimientos imparten media y también educación de adultos (Liceo Carmen Aurora Rodríguez, Liceo Diego Portales y Colegio Alta Cordillera). El Aula Hospitalaria atiende a estudiantes de media internados, y el Colegio Komvux funciona como reingreso educativo: ambos se mantienen porque registran media regular, pero conviene revisarlos según el uso que se le dé a la base.
