Workbook

Sheet Base
A1: Establecimientos educacionales de la comuna de Coquimbo
A2: Corte: 05.10.2026. Universo: 154 establecimientos con RBD vigentes en el Directorio Oficial MINEDUC 2025 + 9 jardines VTF del SLEP Puerto Cordillera. Gobiernos estudiantiles 2026 de la educación pública integrados según nómina del SLEP. Actualización 23.10.2026: se agregan las 2 instituciones de educación superior con sede en la comuna (Ceduc UCN y UCN Sede Coquimbo). Celdas amarillas: por completar.
A4: N° | B4: RBD | C4: Nombre | D4: Dependencia | E4: Niveles | F4: Zona | G4: Matrícula 2025 | H4: Director | I4: Fono institucional | J4: E-mail | K4: Dirección | L4: Aniversario | M4: Año de fundación | N4: Reconocimiento oficial (MINEDUC) | O4: Presidente/a centro de estudiantes | P4: Cargo (gobierno estudiantil) | Q4: Correo presidente/a CEAL | R4: Fuente CEAL | S4: Sitio web | T4: Sostenedor | U4: Latitud | V4: Longitud | W4: Fuente contacto | X4: Fuente aniversario | Y4: Observaciones
A5: 1 | B5: 623 | C5: Centro Laboral Jean Piaget | D5: Pública (SLEP Puerto Cordillera) | E5: Especial | F5: Urbana | G5: 56 | H5: Rosa Pérez Ramírez | I5: +56 51 231 4914 | J5: esc.jeanpiaget@slepuertocordillera.cl | K5: Miraflores N°525 – B | L5: 30 de junio | M5: 1972 | N5: Resolución exenta 10036 de fecha 15/12/1981 | O5: Diana Eliza Campos Barrera | P5: Presidenta de gobierno estudiantil | Q5: esc.jeanpiaget@slepuertocordillera.cl (correo del establecimiento) | R5: SLEP Puerto Cordillera, nómina presidentas/es centros de estudiantes 2026 | T5: Servicio Local De Educación Pública Puerto Cordillera | U5: -29.967146 | V5: -71.326401 | W5: SLEP Puerto Cordillera, tabla de establecimientos (act. 07.05.2026) | X5: PEI del establecimiento (MINEDUC)
A6: 2 | B6: 616 | C6: Colegio Cardenal Jose Maria Caro | D6: Pública (SLEP Puerto Cordillera) | E6: Parvularia, Básica, Media HC | F6: Urbana | G6: 651 | H6: Domitila Pérez Díaz | I6: +56 44 369 1107 | J6: esc.cardenaljosemariacaro@slepuertocordillera.cl | K6: Cardenal Caro N°701- sector El Llano | L6: Sin información | M6: Sin información | N6: Resolución exenta 10049 de fecha 15/12/1981 | O6: Annais Victoria Badilla Valdivia | P6: Presidenta | Q6: annaisbadillavaldivia@gmail.com | R6: SLEP Puerto Cordillera, nómina presidentas/es centros de estudiantes 2026 | T6: Servicio Local De Educación Pública Puerto Cordillera | U6: -29.96734 | V6: -71.339104 | W6: SLEP Puerto Cordillera, tabla de establecimientos (act. 07.05.2026) | Y6: Director según tabla SLEP; MIME registra a Eduardo Andrés Alfaro Espinoza: confirmar
A7: 3 | B7: 629 | C7: Colegio Pablo Neruda | D7: Pública (SLEP Puerto Cordillera) | E7: Parvularia, Básica, Media HC, Media TP | F7: Rural | G7: 741 | H7: Manuel Salas López | I7: +56 51 223 9861 | J7: col.pabloneruda@slepuertocordillera.cl | K7: RUTA D409 Km 18 – Camino Interior N°9505 – Pan de Azúcar | L7: Julio (celebración) | M7: 1891 | N7: Resolución exenta 10046 de fecha 15/12/1981 | O7: Antonia Vera Cofré | P7: Presidenta | Q7: cofre.antonia30@gmail.com | R7: SLEP Puerto Cordillera, nómina presidentas/es centros de estudiantes 2026 | T7: Servicio Local De Educación Pública Puerto Cordillera | U7: -30.05068 | V7: -71.252403 | W7: SLEP Puerto Cordillera, tabla de establecimientos (act. 07.05.2026) | X7: Noticias SLEP Puerto Cordillera (128 años, julio 2019) | Y7: Director según tabla SLEP; MIME registra a Carla Francisca Álvarez Ibáñez: confirmar
A8: 4 | B8: 617 | C8: Colegio Santa Cecilia | D8: Pública (SLEP Puerto Cordillera) | E8: Parvularia, Básica | F8: Urbana | G8: 239 | H8: Carola Alejandra Gutiérrez Piqueres | I8: +56 44 369 5859 | J8: col.santacecilia@slepuertocordillera.cl | K8: Borgoño N°1100 – sector parte Alta | L8: 7 de agosto | M8: 1963 | N8: Resolución exenta 10050 de fecha 01/01/2002 | O8: Renato Martinez Torres | P8: Presidente | Q8: maticito_26@hotmail.com | R8: SLEP Puerto Cordillera, nómina presidentas/es centros de estudiantes 2026 | T8: Servicio Local De Educación Pública Puerto Cordillera | U8: -29.953659 | V8: -71.343246 | W8: SLEP Puerto Cordillera, tabla de establecimientos (act. 07.05.2026) | X8: PEI del establecimiento (MINEDUC); Noticias SLEP Puerto Cordillera | Y8: Asumió por concurso de Alta Dirección Pública (SLEP, noticia 04.05.2026); la tabla del SLEP aún muestra al director anterior
A9: 5 | B9: 613 | C9: Colegio de Artes Claudio Arrau | D9: Pública (SLEP Puerto Cordillera) | E9: Parvularia, Básica, Media HC | F9: Urbana | G9: 755 | H9: Jorge Alberto Ríos Ruiz | I9: +56 51 232 8751 | J9: col.artesclaudioarrau@slepuertocordillera.cl | K9: Avda. Videla N°199 | L9: 3 de septiembre (PEI); el acto se ha celebrado en mayo | M9: 1834 | N9: Resolución exenta 10034 de fecha 15/12/1981 | O9: Amparo Daira Yañez Nuñez | P9: Presidenta | Q9: ayanezn2872@gmail.com | R9: SLEP Puerto Cordillera, nómina presidentas/es centros de estudiantes 2026 | S9: www.arraucoquimbo.cl | T9: Servicio Local De Educación Pública Puerto Cordillera | U9: -29.961269 | V9: -71.338287 | W9: SLEP Puerto Cordillera, tabla de establecimientos (act. 07.05.2026) | X9: PEI del establecimiento (MINEDUC); Noticias SLEP Puerto Cordillera (177° aniversario, mayo 2019) | Y9: Según MIME; el director que figura en la tabla del SLEP (Carlos Videla) pasó al IAC Estado de Israel en mayo de 2026: confirmar si es titular o subrogante
A10: 6 | B10: 630 | C10: Colegio la Herradura | D10: Pública (SLEP Puerto Cordillera) | E10: Parvularia, Básica | F10: Urbana | G10: 358 | H10: Ernesto Lizana Valdivia | I10: +56 51 226 0370 | J10: col.laherradura@slepuertocordillera.cl | K10: La Ermita N°355 – La Herradura | L10: Octubre (celebración) | M10: 1853 | N10: Resolución exenta 10051 de fecha 15/12/1981 | O10: Damián Rojas Contreras | P10: Presidente | Q10: col.laherradura@slepuertocordillera.cl (correo del establecimiento) | R10: SLEP Puerto Cordillera, nómina presidentas/es centros de estudiantes 2026 | T10: Servicio Local De Educación Pública Puerto Cordillera | U10: -29.98613 | V10: -71.361214 | W10: SLEP Puerto Cordillera, tabla de establecimientos (act. 07.05.2026) | X10: PEI del establecimiento (MINEDUC); Noticias SLEP Puerto Cordillera | Y10: Director según tabla SLEP; MIME registra a Sergio Eduardo Carrasset Godoy: confirmar
A11: 7 | B11: 626 | C11: Escuela Basica David Leon Tapia | D11: Pública (SLEP Puerto Cordillera) | E11: Parvularia, Básica, Especial | F11: Urbana | G11: 668 | H11: Juan Humberto Cabrera Olivares | I11: +56 44 369 1097 | J11: esc.davidleontapia@slepuertocordillera.cl | K11: Federico Silva N°210 – Tongoy | L11: 17 de febrero | M11: 1872 | N11: Resolución exenta 10067 de fecha 15/12/1981 | O11: Amaral Véliz Rojas | P11: Presidenta de gobierno estudiantil | Q11: amaralveliz339@gmail.com | R11: SLEP Puerto Cordillera, nómina presidentas/es centros de estudiantes 2026 | T11: Servicio Local De Educación Pública Puerto Cordillera | U11: -30.26317 | V11: -71.489883 | W11: SLEP Puerto Cordillera, tabla de establecimientos (act. 07.05.2026) | X11: PEI del establecimiento (MINEDUC)
A12: 8 | B12: 632 | C12: Escuela Basica Manuel de Salas | D12: Pública (SLEP Puerto Cordillera) | E12: Parvularia, Básica | F12: Urbana | G12: 394 | H12: Marcia Castro Valenzuela | I12: +56 44 369 1101 | J12: esc.manueldesalas@slepuertocordillera.cl | K12: El Ocaso N°310 – Guanaqueros | L12: 27 de marzo | M12: 1947 | N12: Resolución exenta 10038 de fecha 01/01/1981 | O12: Gustavo Alonso Vega Vega | P12: Presidente | Q12: gustavovegavega2@gmail.com | R12: SLEP Puerto Cordillera, nómina presidentas/es centros de estudiantes 2026 | T12: Servicio Local De Educación Pública Puerto Cordillera | U12: -30.19949 | V12: -71.429733 | W12: SLEP Puerto Cordillera, tabla de establecimientos (act. 07.05.2026) | X12: PEI del establecimiento (MINEDUC)
A13: 9 | B13: 621 | C13: Escuela Basica Mario Munoz Silva | D13: Pública (SLEP Puerto Cordillera) | E13: Parvularia, Básica | F13: Urbana | G13: 213 | H13: Jacqueline Palacios Araya | I13: +56 44 368 9693 | J13: esc.mariomunoz@slepuertocordillera.cl | K13: Miraflores N°750 | L13: 16 de junio | M13: 1927 | N13: Resolución exenta 10059 de fecha 15/12/1981 | O13: Monserrat Pérez Olivares | P13: Presidenta | Q13: esc.mariomunoz@slepuertocordillera.cl (correo del establecimiento) | R13: SLEP Puerto Cordillera, nómina presidentas/es centros de estudiantes 2026 | T13: Servicio Local De Educación Pública Puerto Cordillera | U13: -29.967279 | V13: -71.327621 | W13: SLEP Puerto Cordillera, tabla de establecimientos (act. 07.05.2026) | X13: PEI del establecimiento (MINEDUC) | Y13: Director según tabla SLEP; MIME registra a Patricia Milena Maya Podestá: confirmar
A14: 10 | B14: 13557 | C14: Escuela Basica Republica de Italia | D14: Pública (SLEP Puerto Cordillera) | E14: Parvularia, Básica | F14: Urbana | G14: 263 | H14: Jenny Vivian Salinas Rosales | I14: +56 44 369 1091 | J14: esc.republicadeitalia@slepuertocordillera.cl | K14: Regimiento Arica N°1401 | L14: 30 de junio (resolución); acto en julio | M14: 2005 | N14: Resolución exenta 2263 de fecha 30/06/2005 | O14: Micaela Acebo Flores | P14: Presidenta | Q14: esc.republicadeitalia@slepuertocordillera.cl (correo del establecimiento) | R14: SLEP Puerto Cordillera, nómina presidentas/es centros de estudiantes 2026 | T14: Servicio Local De Educación Pública Puerto Cordillera | U14: -29.95595 | V14: -71.247238 | W14: SLEP Puerto Cordillera, tabla de establecimientos (act. 07.05.2026) | X14: PEI del establecimiento (MINEDUC); Noticias SLEP Puerto Cordillera | Y14: Asumió por concurso de Alta Dirección Pública (SLEP, noticia 04.05.2026); la tabla del SLEP aún muestra al director anterior
A15: 11 | B15: 615 | C15: Escuela Coquimbo | D15: Pública (SLEP Puerto Cordillera) | E15: Parvularia, Básica | F15: Urbana | G15: 244 | H15: Vanessa Ortega Valencia | I15: +56 51 232 0226 | J15: esc.coquimbo@slepuertocordillera.cl | K15: Bilbao N°115 | L15: 11 de septiembre | M15: 1901 | N15: Resolución exenta 194 de fecha 29/03/1983 | O15: Thiago Stephano Cruzado Felipe | P15: Presidente de gobierno estudiantil | Q15: cruzadofelipethiago@gmail.com | R15: SLEP Puerto Cordillera, nómina presidentas/es centros de estudiantes 2026 | T15: Servicio Local De Educación Pública Puerto Cordillera | U15: -29.954359 | V15: -71.336273 | W15: SLEP Puerto Cordillera, tabla de establecimientos (act. 07.05.2026) | X15: PEI del establecimiento (MINEDUC); Noticias SLEP Puerto Cordillera
A16: 12 | B16: 624 | C16: Escuela Diferencial Juan Sandoval C. | D16: Pública (SLEP Puerto Cordillera) | E16: Especial | F16: Urbana | G16: 74 | H16: Marjorie Alejandra Flores Blanco | I16: +56 51 232 2023 | J16: esc.juansandoval@slepuertocordillera.cl | K16: Santa Elena N°385 | L16: 20 de marzo | M16: 1973 | N16: Resolución exenta 10037 de fecha 15/12/1981 | O16: Chydan Espinoza Torres | P16: Presidente | Q16: esc.juansandoval@slepuertocordillera.cl (correo del establecimiento) | R16: SLEP Puerto Cordillera, nómina presidentas/es centros de estudiantes 2026 | T16: Servicio Local De Educación Pública Puerto Cordillera | U16: -29.96769 | V16: -71.324165 | W16: SLEP Puerto Cordillera, tabla de establecimientos (act. 07.05.2026) | X16: PEI del establecimiento (MINEDUC)
A17: 13 | B17: 612 | C17: Escuela Guillermo Cereceda | D17: Pública (SLEP Puerto Cordillera) | E17: Parvularia, Básica | F17: Urbana | G17: 276 | H17: Carolina Castillo Lazo | I17: +56 44 369 2440 | J17: esc.guillermocereceda@slepuertocordillera.cl | K17: Santiago Amengual N°364 – Pob. San Juan | L17: 20 de septiembre | M17: 1970 | N17: Resolución exenta 10033 de fecha 15/12/1981 | O17: Maite Godoy Brañas | P17: Presidente de gobierno estudiantil | Q17: esc.guillermocereceda@slepuertocordillera.cl (correo del establecimiento) | R17: SLEP Puerto Cordillera, nómina presidentas/es centros de estudiantes 2026 | T17: Servicio Local De Educación Pública Puerto Cordillera | U17: -29.971701 | V17: -71.325447 | W17: SLEP Puerto Cordillera, tabla de establecimientos (act. 07.05.2026) | X17: PEI del establecimiento (MINEDUC)
A18: 14 | B18: 620 | C18: Escuela Jose Alfaro Alfaro | D18: Pública (SLEP Puerto Cordillera) | E18: Parvularia, Básica | F18: Urbana | G18: 513 | H18: Samuel Hernández Fajardo | I18: +56 44 369 2439 | J18: esc.joseagustinalfaro@slepuertocordillera.cl | K18: Rafael Sotomayor N°105 – Ts. Blancas | L18: 29 de abril | M18: 1965 | N18: Resolución exenta 10058 de fecha 15/01/1981 | O18: Richard Ronaldo Rolón Gonzáles | P18: Presidente | Q18: rolonrichardgonzales@gmail.com | R18: SLEP Puerto Cordillera, nómina presidentas/es centros de estudiantes 2026 | S18: www.joseagustinalfaro.net | T18: Servicio Local De Educación Pública Puerto Cordillera | U18: -29.957069 | V18: -71.261627 | W18: SLEP Puerto Cordillera, tabla de establecimientos (act. 07.05.2026) | X18: PEI del establecimiento (MINEDUC); Noticias SLEP Puerto Cordillera (60 años, mayo 2025)
A19: 15 | B19: 13562 | C19: Escuela Juan Pablo II | D19: Pública (SLEP Puerto Cordillera) | E19: Parvularia, Básica | F19: Urbana | G19: 171 | H19: Rodrigo Gonzalez Lobos | I19: +56 44 369 2438 | J19: esc.juanpabloii@slepuertocordillera.cl | K19: Camino al Faro N°50 sector Parte Alta | L19: 14 de marzo (inicio); acto 2025 en noviembre | M19: 2005 | N19: Resolución exenta 1502 de fecha 10/05/2005 | O19: Renata Ibacache Madrid | P19: Presidenta | Q19: renata.ibacache.2014@gmail.com | R19: SLEP Puerto Cordillera, nómina presidentas/es centros de estudiantes 2026 | T19: Servicio Local De Educación Pública Puerto Cordillera | U19: -29.936899 | V19: -71.339867 | W19: SLEP Puerto Cordillera, tabla de establecimientos (act. 07.05.2026) | X19: PEI del establecimiento (MINEDUC); Noticias SLEP Puerto Cordillera
A20: 16 | B20: 637 | C20: Escuela Lucila Godoy Alcayaga | D20: Pública (SLEP Puerto Cordillera) | E20: Parvularia, Básica | F20: Urbana | G20: 256 | H20: Mario Cerda Galván | I20: +56 51 227 7859 | J20: esc.lucilagodoyalcayaga@slepuertocordillera.cl | K20: Avda. La Cantera Nº 2055 – sector Cantera Baja | L20: Sin información | M20: Sin información | N20: Resolución exenta 10048 de fecha 02/01/1981 | O20: Martina Sepúlveda | P20: Presidenta | Q20: esc.lucilagodoyalcayaga@slepuertocordillera.cl (correo del establecimiento) | R20: SLEP Puerto Cordillera, nómina presidentas/es centros de estudiantes 2026 | T20: Servicio Local De Educación Pública Puerto Cordillera | U20: -29.97381 | V20: -71.299103 | W20: SLEP Puerto Cordillera, tabla de establecimientos (act. 07.05.2026)
A21: 17 | B21: 13560 | C21: Escuela Padre Alberto Hurtado Cruchaga | D21: Pública (SLEP Puerto Cordillera) | E21: Parvularia, Básica | F21: Urbana | G21: 199 | H21: Constanza Alejandra Robles Valdivia | I21: +56 44 369 2435 | J21: esc.padrealbertohurtado@slepuertocordillera.cl | K21: Bellamar N°1111 sector Parte Alta | L21: 7 de marzo | M21: 2005 | N21: Resolución exenta 773 de fecha 17/03/2005 | O21: Florencia Marinzulic Ramos | P21: Presidenta | Q21: esc.padrealbertohurtado@slepuertocordillera.cl (correo del establecimiento) | R21: SLEP Puerto Cordillera, nómina presidentas/es centros de estudiantes 2026 | S21: https://sites.google.com/slepuertocordillera.cl/escuelapahccoquimbo/boletín-informativo-no | T21: Servicio Local De Educación Pública Puerto Cordillera | U21: -29.951389 | V21: -71.349281 | W21: SLEP Puerto Cordillera, tabla de establecimientos (act. 07.05.2026) | X21: PEI del establecimiento (MINEDUC)
A22: 18 | B22: 614 | C22: Escuela Presidente Anibal Pinto | D22: Pública (SLEP Puerto Cordillera) | E22: Parvularia, Básica | F22: Urbana | G22: 277 | H22: Maritza Fajardo Basaure | I22: +56 44 369 2433 | J22: esc.presidenteanibalpinto@slepuertocordillera.cl | K22: Aníbal Pinto N°1319 | L22: 9 de octubre | M22: 1944 | N22: Resolución exenta 10035 de fecha 15/12/1981 | O22: Maite Tarsetti | P22: Presidenta | Q22: tete.tarsetti@gmail.com | R22: SLEP Puerto Cordillera, nómina presidentas/es centros de estudiantes 2026 | S22: www.eapinto.cl | T22: Servicio Local De Educación Pública Puerto Cordillera | U22: -29.95573 | V22: -71.339958 | W22: SLEP Puerto Cordillera, tabla de establecimientos (act. 07.05.2026) | X22: PEI del establecimiento (MINEDUC); Noticias SLEP Puerto Cordillera
A23: 19 | B23: 13559 | C23: Escuela Republica de Grecia | D23: Pública (SLEP Puerto Cordillera) | E23: Parvularia, Básica | F23: Urbana | G23: 377 | H23: Juan Juica Cisternas | I23: +56 51 226 8024 | J23: esc.republicadegrecia@slepuertocordillera.cl | K23: Eugenio Marzal N°288 – Villa Portugal | L23: 10 de mayo (resolución de creación) | M23: 2005 | N23: Resolución exenta 1504 de fecha 10/05/2005 | O23: Bárbara Sophia Peraza Lopez | P23: Presidente | Q23: barbaraperaza988@gmail.com | R23: SLEP Puerto Cordillera, nómina presidentas/es centros de estudiantes 2026 | T23: Servicio Local De Educación Pública Puerto Cordillera | U23: -29.98612 | V23: -71.332314 | W23: SLEP Puerto Cordillera, tabla de establecimientos (act. 07.05.2026) | X23: PEI del establecimiento (MINEDUC) | Y23: Director según tabla SLEP; MIME registra a Ricardo Antonio Ubilla Astudillo: confirmar
A24: 20 | B24: 631 | C24: Escuela San Rafael | D24: Pública (SLEP Puerto Cordillera) | E24: Parvularia, Básica | F24: Urbana | G24: 418 | H24: Carmen Gloria Morales Loezar | I24: +56 51 224 1864 | J24: esc.sanrafael@slepuertocordillera.cl | K24: Ruta D409 – Km.13 – Pan de Azúcar | L24: Abril (celebración) | M24: 1951 | N24: Resolución exenta 00184 de fecha 28/03/1989 | O24: Bastián Godoy Galaz | P24: Presidente | Q24: esc.sanrafael@slepuertocordillera.cl (correo del establecimiento) | R24: SLEP Puerto Cordillera, nómina presidentas/es centros de estudiantes 2026 | S24: www.escuelasanrafaelcoquimbo.cl | T24: Servicio Local De Educación Pública Puerto Cordillera | U24: -30.01071 | V24: -71.256767 | W24: SLEP Puerto Cordillera, tabla de establecimientos (act. 07.05.2026) | X24: Noticias SLEP Puerto Cordillera (68° aniversario, abril 2019)
A25: 21 | B25: 618 | C25: Escuela Santo Tomas de Aquino | D25: Pública (SLEP Puerto Cordillera) | E25: Parvularia, Básica | F25: Urbana | G25: 632 | H25: Verónica Soto Pereira | I25: +56 44 369 0450 | J25: esc.santotomasdeaquino@slepuertocordillera.cl | K25: Talca N°1099 – Ts. Blancas | L25: 19 de abril (inicio oficial: 22 de octubre) | M25: 1976 | N25: Resolución exenta 10053 de fecha 15/12/1981 | O25: Jorge Jaramillo Guzmán | P25: Presidente | Q25: esc.santotomasdeaquino@slepuertocordillera.cl (correo del establecimiento) | R25: SLEP Puerto Cordillera, nómina presidentas/es centros de estudiantes 2026 | T25: Servicio Local De Educación Pública Puerto Cordillera | U25: -29.962 | V25: -71.254204 | W25: SLEP Puerto Cordillera, tabla de establecimientos (act. 07.05.2026) | X25: PEI del establecimiento (MINEDUC)
A26: 22 | B26: 625 | C26: Escuela Tomasa Olivares Caamano | D26: Pública (SLEP Puerto Cordillera) | E26: Parvularia, Básica | F26: Urbana | G26: 187 | H26: Felipe Rojas Belmar | I26: +56 51 231 9295 | J26: esc.tomasaolivarescaamano@slepuertocordillera.cl | K26: Avda. Guacolda N°1945 | L26: Sin información | M26: 1986 | N26: Resolución exenta 29 de fecha 07/01/1991 | O26: Constanza Campusano Manríquez | P26: Presidenta del gobierno escolar | Q26: dmenfermera@gmail.com | R26: SLEP Puerto Cordillera, nómina presidentas/es centros de estudiantes 2026 | S26: sites.google.com/view/escuela-deportiva-digital/ | T26: Servicio Local De Educación Pública Puerto Cordillera | U26: -29.96139 | V26: -71.348793 | W26: SLEP Puerto Cordillera, tabla de establecimientos (act. 07.05.2026) | X26: PEI del establecimiento (MINEDUC)
A27: 23 | B27: 638 | C27: Escuela de Camarones | D27: Pública (SLEP Puerto Cordillera) | F27: Rural | G27: 0 | H27: Sin información | I27: +56 9 8308 7609 | J27: haroldo_veliz@hotmail.com | K27: Camarones Km. 416 -ruta 5 | L27: Sin información | M27: Sin información | N27: Resolución exenta 10055 de fecha 15/12/1981 | O27: No aplica | T27: Servicio Local De Educación Pública Puerto Cordillera | U27: -30.436291 | V27: -71.379044 | W27: MINEDUC, Ficha del Establecimiento (MIME), consulta 05.10.2026 | Y27: Celular antiguo de 8 dígitos, se antepuso 9: verificar; Sin matrícula 2025 y fuera del listado del SLEP: probable receso; Sin matrícula informada en 2025; Sin director informado en MIME
A28: 24 | B28: 634 | C28: Escuela de Huachalalume | D28: Pública (SLEP Puerto Cordillera) | E28: Básica | F28: Rural | G28: 47 | H28: Karla Patricia Muñoz Jerez | I28: +56 9 4077 0336 | J28: esc.huachalalume@slepuertocordillera.cl | K28: Calle Única s/n | L28: 16 de agosto | M28: 1965 | N28: Resolución exenta 10041 de fecha 15/12/1981 | O28: Matilde Collao | P28: Presidenta | Q28: esc.huachalalume@slepuertocordillera.cl (correo del establecimiento) | R28: SLEP Puerto Cordillera, nómina presidentas/es centros de estudiantes 2026 | T28: Servicio Local De Educación Pública Puerto Cordillera | U28: -29.97542 | V28: -71.219368 | W28: SLEP Puerto Cordillera, tabla de establecimientos (act. 07.05.2026) | X28: PEI del establecimiento (MINEDUC); Noticias SLEP Puerto Cordillera | Y28: Teléfono tomado de MIME (el SLEP no publica uno); Docente encargada desde marzo de 2025 (SLEP, noticia 06.03.2025) y según MIME; la tabla del SLEP muestra al encargado anterior
A29: 25 | B29: 628 | C29: Escuela de Penuelas | D29: Pública (SLEP Puerto Cordillera) | E29: Parvularia, Básica | F29: Urbana | G29: 245 | H29: Jenny Hill Sepúlveda | I29: +56 44 369 1292 | J29: esc.penuelas@slepuertocordillera.cl | K29: Avda. Los Pescadores N°4870 | L29: 26 de agosto | M29: 1952 | N29: Resolución exenta 10054 de fecha 15/12/1981 | O29: Diego Rojas | P29: Presidente | Q29: esc.penuelas@slepuertocordillera.cl (correo del establecimiento) | R29: SLEP Puerto Cordillera, nómina presidentas/es centros de estudiantes 2026 | T29: Servicio Local De Educación Pública Puerto Cordillera | U29: -29.95158 | V29: -71.296204 | W29: SLEP Puerto Cordillera, tabla de establecimientos (act. 07.05.2026) | X29: PEI del establecimiento (MINEDUC)
A30: 26 | B30: 644 | C30: Escuela de Puerto Aldea | D30: Pública (SLEP Puerto Cordillera) | E30: Básica | F30: Rural | G30: 34 | H30: Nilsson Véliz Véliz | I30: +56 9 8524 2056 | J30: esc.puertoaldea@slepuertocordillera.cl | K30: Km. 68 Puerto Aldea | L30: 8 de octubre | M30: 1954 | N30: Resolución exenta 10065 de fecha 15/12/1981 | O30: Mía Pascal Tapia Araya | P30: Presidenta | Q30: esc.puertoaldea@slepuertocordillera.cl (correo del establecimiento) | R30: SLEP Puerto Cordillera, nómina presidentas/es centros de estudiantes 2026 | T30: Servicio Local De Educación Pública Puerto Cordillera | U30: -30.29287 | V30: -71.609261 | W30: SLEP Puerto Cordillera, tabla de establecimientos (act. 07.05.2026) | X30: PEI del establecimiento (MINEDUC)
A31: 27 | B31: 643 | C31: Escuela de Tambillos | D31: Pública (SLEP Puerto Cordillera) | E31: Parvularia, Básica | F31: Rural | G31: 200 | H31: Javier Antonio Monardes Tapia | I31: +56 44 369 2423 | J31: esc.tambillos@slepuertocordillera.cl | K31: Esmeralda N°35 – Tambillos | L31: Noviembre (celebración) | M31: 1880 | N31: Resolución exenta 1918 de fecha 21/12/1982 | O31: Maira Leyton Cerda | P31: Presidenta de gobierno estudiantil | Q31: esc.tambillos@slepuertocordillera.cl (correo del establecimiento) | R31: SLEP Puerto Cordillera, nómina presidentas/es centros de estudiantes 2026 | T31: Servicio Local De Educación Pública Puerto Cordillera | U31: -30.197321 | V31: -71.223686 | W31: SLEP Puerto Cordillera, tabla de establecimientos (act. 07.05.2026) | X31: Noticias SLEP Puerto Cordillera (145 años, nov. 2025); el PEI indica 1900
A32: 28 | B32: 635 | C32: Escuela de Totoralillo | D32: Pública (SLEP Puerto Cordillera) | E32: Básica | F32: Rural | G32: 17 | H32: Robert Salas Pizarro | I32: +56 51 231 0184 | J32: esc.totoralillo@slepuertocordillera.cl | K32: Totoralillo s/n | L32: 8 de marzo | M32: 1960 | N32: Resolución exenta 10043 de fecha 15/12/1981 | O32: Simón Alejandro Vega Véliz | P32: Presidente | Q32: simonvega020@gmail.com | R32: SLEP Puerto Cordillera, nómina presidentas/es centros de estudiantes 2026 | T32: Servicio Local De Educación Pública Puerto Cordillera | U32: -30.064871 | V32: -71.366211 | W32: SLEP Puerto Cordillera, tabla de establecimientos (act. 07.05.2026) | X32: PEI del establecimiento (MINEDUC) | Y32: Teléfono tomado de MIME (el SLEP no publica uno)
A33: 29 | B33: 642 | C33: Escuela de el Penon | D33: Pública (SLEP Puerto Cordillera) | E33: Básica | F33: Rural | G33: 167 | H33: Luis Esteban Araya Valdivia | I33: +56 44 369 1114 | J33: esc.elpenon@slepuertocordillera.cl | K33: Camino Coquimbo O’Higgins s/n | L33: Sin información | M33: c. 1920 | N33: Resolución exenta 10063 de fecha 15/12/1981 | O33: Erick Aguilera Álvarez | P33: Presidente | Q33: esc.elpenon@slepuertocordillera.cl (correo del establecimiento) | R33: SLEP Puerto Cordillera, nómina presidentas/es centros de estudiantes 2026 | T33: Servicio Local De Educación Pública Puerto Cordillera | U33: -30.138849 | V33: -71.215828 | W33: SLEP Puerto Cordillera, tabla de establecimientos (act. 07.05.2026) | X33: PEI del establecimiento (MINEDUC)
A34: 30 | B34: 645 | C34: Escuela de el Tangue | D34: Pública (SLEP Puerto Cordillera) | E34: Básica | F34: Rural | G34: 14 | H34: Kamila Muñoz Bustamantes | I34: +56 9 8308 7609 | J34: esc.eltangue@slepuertocordillera.cl | K34: Km.60 Hacienda El Tangue | L34: 12 de octubre | M34: 1965 | N34: Resolución exenta 10066 de fecha 15/12/1981 | O34: Alonso Marín Bernal | P34: Presidente | Q34: esc.eltangue@slepuertocordillera.cl (correo del establecimiento) | R34: SLEP Puerto Cordillera, nómina presidentas/es centros de estudiantes 2026 | T34: Servicio Local De Educación Pública Puerto Cordillera | U34: -30.34646 | V34: -71.558617 | W34: SLEP Puerto Cordillera, tabla de establecimientos (act. 07.05.2026) | X34: PEI del establecimiento (MINEDUC) | Y34: Teléfono tomado de MIME (el SLEP no publica uno)
A35: 31 | B35: 639 | C35: Escuela de las Barrancas | D35: Pública (SLEP Puerto Cordillera) | E35: Parvularia, Básica | F35: Rural | G35: 135 | H35: Sebastian Fernandez Rojas | I35: +56 44 369 2425 | J35: esc.lasbarrancas@slepuertocordillera.cl | K35: Ruta D-43 Km. 37 | L35: 14 de junio | M35: 1969 | N35: Resolución exenta 10060 de fecha 15/12/1981 | O35: Amalia González Véliz | P35: Presidenta de gobierno estudiantil | Q35: esc.lasbarrancas@slepuertocordillera.cl (correo del establecimiento) | R35: SLEP Puerto Cordillera, nómina presidentas/es centros de estudiantes 2026 | T35: Servicio Local De Educación Pública Puerto Cordillera | U35: -30.213289 | V35: -71.257874 | W35: SLEP Puerto Cordillera, tabla de establecimientos (act. 07.05.2026) | X35: PEI del establecimiento (MINEDUC)
A36: 32 | B36: 641 | C36: Escuela de las Cardas | D36: Pública (SLEP Puerto Cordillera) | E36: Básica | F36: Rural | G36: 24 | H36: Celedonia Jorquera Rivera | I36: +56 9 3448 7519 | J36: esc.lascardas@slepuertocordillera.cl | K36: Km.45 de la Ruta 43 | L36: 21 de noviembre | M36: c. 1928-1935 | N36: Resolución exenta 10062 de fecha 15/12/1981 | O36: Martin Alexis Cortés Juarez | P36: Presidente | Q36: martinalexis.cortes.juarez@gmail.com | R36: SLEP Puerto Cordillera, nómina presidentas/es centros de estudiantes 2026 | T36: Servicio Local De Educación Pública Puerto Cordillera | U36: -30.27844 | V36: -71.252502 | W36: SLEP Puerto Cordillera, tabla de establecimientos (act. 07.05.2026) | X36: PEI del establecimiento (MINEDUC) (fecha que asume la comunidad) | Y36: Teléfono tomado de MIME (el SLEP no publica uno)
A37: 33 | B37: 13558 | C37: Instituto de Adm. y Comercio Estado de Israel | D37: Pública (SLEP Puerto Cordillera) | E37: Básica, Media TP | F37: Urbana | G37: 592 | H37: Carlos Videla Bonilla | I37: +56 51 231 9395 | J37: iac.estadodeisrael@slepuertocordillera.cl | K37: Manuel Jesús Rivera N°320 – sector San Juan | L37: Mayo (celebración) | M37: 2005 | N37: Resolución exenta 1452 de fecha 06/05/2005 | O37: Catalina Pavez Fuenzalida | P37: Presidenta | Q37: catalinapavezfuenzalida@gmail.com | R37: SLEP Puerto Cordillera, nómina presidentas/es centros de estudiantes 2026 | T37: Servicio Local De Educación Pública Puerto Cordillera | U37: -29.970631 | V37: -71.325447 | W37: SLEP Puerto Cordillera, tabla de establecimientos (act. 07.05.2026) | X37: Noticias SLEP Puerto Cordillera (14 años, mayo 2019) | Y37: Asumió por concurso de Alta Dirección Pública (SLEP, noticia 04.05.2026); la tabla del SLEP aún muestra al director anterior
A38: 34 | B38: 13561 | C38: Lic.De Cienc.Y Hum.San Josemaria Escriva | D38: Pública (SLEP Puerto Cordillera) | E38: Básica, Media HC | F38: Urbana | G38: 519 | H38: Jaime Miranda Manríquez | I38: +56 51 226 8461 | J38: lic.josemariaescriva@slepuertocordillera.cl | K38: Los Clarines N°1871 | L38: 1 de septiembre | M38: 2005 | N38: Resolución exenta 1451 de fecha 06/05/2005 | O38: Ángela Muñoz Véliz | P38: Presidenta | Q38: angemunozve08@gmail.com | R38: SLEP Puerto Cordillera, nómina presidentas/es centros de estudiantes 2026 | T38: Servicio Local De Educación Pública Puerto Cordillera | U38: -29.990379 | V38: -71.331596 | W38: SLEP Puerto Cordillera, tabla de establecimientos (act. 07.05.2026) | X38: PEI del establecimiento (MINEDUC); Noticias SLEP Puerto Cordillera
A39: 35 | B39: 609 | C39: Liceo Bicentenario de Excelencia Instituto Superior de Comercio de Coquimbo | D39: Pública (SLEP Puerto Cordillera) | E39: Media TP | F39: Urbana | G39: 838 | H39: Fernando Carvajal Araya | I39: +56 51 232 1092 / +56 51 231 3968 | J39: isc.coquimbo@slepuertocordillera.cl | K39: Doctor Marín N°367 | L39: 10 de mayo | M39: 1905 | N39: Resolución exenta 339 de fecha 01/03/2018 | O39: Javiera Peña Velásquez | P39: Presidenta | Q39: javierapenavelasquez@gmail.com | R39: SLEP Puerto Cordillera, nómina presidentas/es centros de estudiantes 2026 | S39: www.isccoquimbo.cl | T39: Servicio Local De Educación Pública Puerto Cordillera | U39: -29.96055 | V39: -71.340134 | W39: SLEP Puerto Cordillera, tabla de establecimientos (act. 07.05.2026) | X39: PEI del establecimiento (MINEDUC); Noticias SLEP Puerto Cordillera (120 años, mayo 2025)
A40: 36 | B40: 13461 | C40: Liceo Carmen Aurora Rodriguez Henriquez | D40: Pública (SLEP Puerto Cordillera) | E40: Media HC, Media TP, Adultos | F40: Urbana | G40: 353 | H40: Perla Araya Yañez | I40: +56 51 239 1570 | J40: lic.carmenrodriguez@slepuertocordillera.cl | K40: Dolores Endeiza N°185 – Tongoy | L40: 2 de agosto | M40: 2000 | N40: Resolución exenta 1765 de fecha 02/08/2000 | O40: Sebastián Ignacio Saavedra Henríquez | P40: Presidente | Q40: alex55521332@gmail.com | R40: SLEP Puerto Cordillera, nómina presidentas/es centros de estudiantes 2026 | T40: Servicio Local De Educación Pública Puerto Cordillera | U40: -30.26264 | V40: -71.493401 | W40: SLEP Puerto Cordillera, tabla de establecimientos (act. 07.05.2026) | X40: PEI del establecimiento (MINEDUC); Noticias SLEP Puerto Cordillera
A41: 37 | B41: 611 | C41: Liceo Diego Portales | D41: Pública (SLEP Puerto Cordillera) | E41: Media HC, Media TP, Adultos | F41: Urbana | G41: 474 | H41: Neusy Elizabeth Chelmes Julio | I41: +56 51 232 1015 | J41: lic.diegoportales@slepuertocordillera.cl | K41: Avda. Francisco Varela Oriente N°950 | L41: 5 de abril | M41: 1956 | N41: Resolución exenta 10070 de fecha 15/12/1981 | O41: Sofía Bruna Muñoz | P41: Presidenta de gobierno estudiantil | Q41: sofiab.bruna.munoz@gmail.com | R41: SLEP Puerto Cordillera, nómina presidentas/es centros de estudiantes 2026 | T41: Servicio Local De Educación Pública Puerto Cordillera | U41: -29.95303 | V41: -71.337021 | W41: SLEP Puerto Cordillera, tabla de establecimientos (act. 07.05.2026) | X41: PEI del establecimiento (MINEDUC); Noticias SLEP Puerto Cordillera | Y41: Asumió por concurso de Alta Dirección Pública (SLEP, noticia 04.05.2026); la tabla del SLEP aún muestra al director anterior
...

Sheet Resumen
A1: Resumen de la base
A3: Dependencia | B3: Establecimientos | C3: Matrícula 2025 | D3: Con director informado | E3: Con aniversario (fecha o mes) | F3: Presidente/a CEAL informado | G3: CEAL por completar
A4: Pública (SLEP Puerto Cordillera) | B4: =COUNTIF(Base!$D$5:$D$169,A4) -> 39 | C4: =SUMIF(Base!$D$5:$D$169,A4,Base!$G$5:$G$169) -> 12879 | D4: =COUNTIFS(Base!$D$5:$D$169,A4,Base!$H$5:$H$169,"<>Sin información") -> 38 | E4: =COUNTIFS(Base!$D$5:$D$169,A4,Base!$L$5:$L$169,"<>Sin información") -> 34 | F4: =COUNTIFS(Base!$D$5:$D$169,A4,Base!$O$5:$O$169,"<>Por completar",Base!$O$5:$O$169,"<>No aplica") -> 38 | G4: =COUNTIFS(Base!$D$5:$D$169,A4,Base!$O$5:$O$169,"Por completar") -> 0
A5: Pública VTF (SLEP Puerto Cordillera) | B5: =COUNTIF(Base!$D$5:$D$169,A5) -> 9 | C5: =SUMIF(Base!$D$5:$D$169,A5,Base!$G$5:$G$169) -> 0 | D5: =COUNTIFS(Base!$D$5:$D$169,A5,Base!$H$5:$H$169,"<>Sin información") -> 9 | E5: =COUNTIFS(Base!$D$5:$D$169,A5,Base!$L$5:$L$169,"<>Sin información") -> 1 | F5: =COUNTIFS(Base!$D$5:$D$169,A5,Base!$O$5:$O$169,"<>Por completar",Base!$O$5:$O$169,"<>No aplica") -> 0 | G5: =COUNTIFS(Base!$D$5:$D$169,A5,Base!$O$5:$O$169,"Por completar") -> 0
A6: Particular subvencionado | B6: =COUNTIF(Base!$D$5:$D$169,A6) -> 95 | C6: =SUMIF(Base!$D$5:$D$169,A6,Base!$G$5:$G$169) -> 32690 | D6: =COUNTIFS(Base!$D$5:$D$169,A6,Base!$H$5:$H$169,"<>Sin información") -> 95 | E6: =COUNTIFS(Base!$D$5:$D$169,A6,Base!$L$5:$L$169,"<>Sin información") -> 30 | F6: =COUNTIFS(Base!$D$5:$D$169,A6,Base!$O$5:$O$169,"<>Por completar",Base!$O$5:$O$169,"<>No aplica") -> 0 | G6: =COUNTIFS(Base!$D$5:$D$169,A6,Base!$O$5:$O$169,"Por completar") -> 50
A7: Particular pagado | B7: =COUNTIF(Base!$D$5:$D$169,A7) -> 20 | C7: =SUMIF(Base!$D$5:$D$169,A7,Base!$G$5:$G$169) -> 2451 | D7: =COUNTIFS(Base!$D$5:$D$169,A7,Base!$H$5:$H$169,"<>Sin información") -> 14 | E7: =COUNTIFS(Base!$D$5:$D$169,A7,Base!$L$5:$L$169,"<>Sin información") -> 4 | F7: =COUNTIFS(Base!$D$5:$D$169,A7,Base!$O$5:$O$169,"<>Por completar",Base!$O$5:$O$169,"<>No aplica") -> 0 | G7: =COUNTIFS(Base!$D$5:$D$169,A7,Base!$O$5:$O$169,"Por completar") -> 6
A8: Educación superior TP (CFT) | B8: =COUNTIF(Base!$D$5:$D$169,A8) -> 1 | C8: =SUMIF(Base!$D$5:$D$169,A8,Base!$G$5:$G$169) -> 0 | D8: =COUNTIFS(Base!$D$5:$D$169,A8,Base!$H$5:$H$169,"<>Sin información") -> 1 | E8: =COUNTIFS(Base!$D$5:$D$169,A8,Base!$L$5:$L$169,"<>Sin información") -> 0 | F8: =COUNTIFS(Base!$D$5:$D$169,A8,Base!$O$5:$O$169,"<>Por completar",Base!$O$5:$O$169,"<>No aplica") -> 0 | G8: =COUNTIFS(Base!$D$5:$D$169,A8,Base!$O$5:$O$169,"Por completar") -> 1
A9: Educación superior universitaria (CRUCH) | B9: =COUNTIF(Base!$D$5:$D$169,A9) -> 1 | C9: =SUMIF(Base!$D$5:$D$169,A9,Base!$G$5:$G$169) -> 0 | D9: =COUNTIFS(Base!$D$5:$D$169,A9,Base!$H$5:$H$169,"<>Sin información") -> 1 | E9: =COUNTIFS(Base!$D$5:$D$169,A9,Base!$L$5:$L$169,"<>Sin información") -> 1 | F9: =COUNTIFS(Base!$D$5:$D$169,A9,Base!$O$5:$O$169,"<>Por completar",Base!$O$5:$O$169,"<>No aplica") -> 0 | G9: =COUNTIFS(Base!$D$5:$D$169,A9,Base!$O$5:$O$169,"Por completar") -> 1
A10: Total | B10: =SUM(B4:B9) -> 165 | C10: =SUM(C4:C9) -> 48020 | D10: =SUM(D4:D9) -> 158 | E10: =SUM(E4:E9) -> 70 | F10: =SUM(F4:F9) -> 38 | G10: =SUM(G4:G9) -> 58
A12: La matrícula excluye los jardines VTF, que no tienen RBD en el Directorio MINEDUC.
A13: Las instituciones de educación superior no informan matrícula por RBD; su matrícula queda en Observaciones de la hoja Base.

Sheet Fuentes y notas
A1: Fuentes
A2: Universo | B2: MINEDUC, Directorio Oficial de Establecimientos 2025 (datosabiertos.mineduc.cl), filtrado por comuna 4102 y estado "funcionando". Incluye 12 RBD sin matrícula 2025 (jardines particulares recién reconocidos, una sede de adultos y Escuela de Camarones).
A3: Contacto, establecimientos públicos | B3: SLEP Puerto Cordillera, página "Establecimientos Educacionales" (slepuertocordillera.gob.cl, última edición 07.05.2026). Correos decodificados de la página.
A4: Contacto, establecimientos particulares | B4: MINEDUC, Ficha del Establecimiento (mi.mineduc.cl), consultada el 05.10.2026. La información la carga cada director y puede estar desactualizada.
A5: Cambios de director | B5: SLEP Puerto Cordillera, noticia 04.05.2026: seis directores asumen por Alta Dirección Pública (cuatro en Coquimbo: IAC Estado de Israel, Liceo Diego Portales, Escuela República de Italia y Colegio Santa Cecilia). Se corrigieron en la base.
A6: Aniversarios | B6: Reseñas históricas de los Proyectos Educativos Institucionales (PEI) publicados en MINEDUC y noticias de aniversario del SLEP Puerto Cordillera. Donde no hay fecha de aniversario se indica "Sin información"; la columna de reconocimiento oficial es un dato distinto y no reemplaza al aniversario.
A7: Notas
A8: Teléfonos | B8: Se normalizaron a formato +56. Los números antiguos de 6 dígitos y los celulares de 8 dígitos se convirtieron según las reglas de numeración de 2013 y quedan marcados para verificar en Observaciones.
A9: Directores con dato distinto | B9: En 6 establecimientos públicos la tabla del SLEP y MIME muestran directores distintos (Cardenal Caro, Pablo Neruda, La Herradura, Mario Muñoz, República de Grecia y Claudio Arrau). Se dejó el dato más reciente que se pudo respaldar y se marcó para confirmar.
A10: Presidentes de CEAL | B10: Establecimientos públicos: se integró la nómina 2026 de presidentas y presidentes de centros de estudiantes y gobiernos estudiantiles del SLEP Puerto Cordillera (38 casos, cruzados por establecimiento con su RBD). Coincide con todos los establecimientos públicos de Coquimbo con matrícula; la Escuela de Camarones no figura porque no tuvo matrícula en 2025. Incluye dos escuelas especiales (Jean Piaget y Juan Sandoval) que antes figuraban como "No aplica". Particulares: no hay registro público y quedan 55 en amarillo ("Por completar"). Cuando el correo de la nómina es el institucional del establecimiento, se indica entre paréntesis.
A11: Resguardo de datos | B11: La nómina contiene nombres y correos personales de estudiantes, en su mayoría menores de edad. Usar solo para vinculación institucional, no difundir y no publicar la planilla (Ley 19.628 y Ley 21.719 sobre protección de datos personales). Para contactos formales, preferir el correo institucional del establecimiento con copia a la dirección.
A12: Fuera del universo | B12: No se incluyen los jardines JUNJI de administración directa ni los de Fundación Integra, que no tienen RBD MINEDUC. Tampoco los establecimientos del SLEP ubicados en Andacollo.
A13: Educación superior (23.10.2026) | B13: Se revisaron las sedes de centros de formación técnica (CFT), institutos profesionales (IP) y universidades de la conurbación. Dentro de la comuna de Coquimbo solo operan Ceduc UCN (CFT, casa central en Miraflores 475) y la Universidad Católica del Norte (Campus Guayacán). No hay ningún IP con sede en la comuna. Fuentes: ceduc.cl; Coquimbo Noticias (12.03.2026 y 21.08.2026); El Coquimbano (14.03.2025 y 24.03.2026); Noticias UCN, acreditación Ceduc 2021. El listado de sedes de SIES/MINEDUC no estuvo disponible en línea al momento de la consulta: conviene cruzarlo cuando se publique la matrícula 2026.
A14: Educación superior fuera de la comuna | B14: Funcionan en La Serena y por eso no se incluyen: INACAP, IP y CFT Santo Tomás (Ruta 5 Norte 1068 y Libertad 579), IP AIEP (Huanhuali 105), IP Valle Central (Lautaro 950), CFT Juan Bohon (Balmaceda 2299) y la Universidad de La Serena. El CFT Estatal Región de Coquimbo tiene su casa central en Ovalle; con el municipio conversa la instalación de una sede en Coquimbo, todavía en etapa inicial.
